Workbook

Sheet System Level Data
B2: Title: | C2: A&E Attendances & Emergency Admission monthly statistics, NHS and independent sector organisations in England
B4: Summary: | C4: A&E attendances, performance and emergency admission. Please see the Supplementary ECDS Analysis file for further breakdowns of A&E attendance data, this can be found published below this file on the NHS England Website, this provides attendance data split by age groups, gender, ethnicity, chief complaint and provides a data completeness and quality fact sheet.
B6: Period: | C6: September 26
B7: Source: | C7: SDCS data collection - MSitAE
B8: Basis: | C8: Provider
B9: Published: | C9: 8th October 2026
B10: Revised:
B11: Status: | C11: Published
B12: Contact: | C12: Kerry Evert - england.aedata@nhs.net
B14: System Level Data
D15: A&E attendances | H15: A&E attendances < 4 hours from arrival to admission, transfer or discharge | L15: A&E attendances > 4 hours from arrival to admission, transfer or discharge | P15: Percentage of attendances within 4 hours | T15: Emergency Admissions
B16: Code | C16: System | D16: Type 1 Departments - Major A&E | E16: Type 2 Departments - Single Specialty | F16: Type 3 Departments - Other A&E/Minor Injury Unit | G16: Total attendances | H16: Type 1 Departments - Major A&E | I16: Type 2 Departments - Single Specialty | J16: Type 3 Departments - Other A&E/Minor Injury Unit | K16: Total Attendances < 4 hours | L16: Type 1 Departments - Major A&E | M16: Type 2 Departments - Single Specialty | N16: Type 3 Departments - Other A&E/Minor Injury Unit | O16: Total Attendances > 4 hours | P16: Percentage in 4 hours or less (all) | Q16: Percentage in 4 hours or less (type 1) | R16: Percentage in 4 hours or less (type 2) | S16: Percentage in 4 hours or less (type 3) | T16: Emergency Admissions via Type 1 A&E | U16: Emergency Admissions via Type 2 A&E | V16: Emergency Admissions via Type 3 and 4 A&E | W16: Total Emergency Admissions via A&E | X16: Other Emergency admissions (i.e not via A&E) | Y16: Total Emergency Admissions | Z16: Number of patients spending >4 hours from decision to admit to admission | AA16: Number of patients spending >12 hours from decision to admit to admission
B17: - | C17: - | D17: 1503149 | E17: 55513 | F17: 886081 | G17: 2444743 | H17: 910567 | I17: 52395 | J17: 855030 | K17: 1817992 | L17: 592582 | M17: 3118 | N17: 31051 | O17: 626751 | P17: 0.74363318 | Q17: 0.60577295 | R17: 0.94383298 | S17: 0.96495693 | T17: 394675 | U17: 1534 | V17: 5107 | W17: 401316 | X17: 134842 | Y17: 536158 | Z17: 129199 | AA17: 50582
B19: D7T5G | C19: NHS Essex Integrated Care Board | D19: 37862 | E19: 0 | F19: 11080 | G19: 48942 | H19: 24290 | I19: 0 | J19: 10719 | K19: 35009 | L19: 13572 | M19: 0 | N19: 361 | O19: 13933 | P19: 0.71531609 | Q19: 0.64154033 | R19: - | S19: 0.96741877 | T19: 10916 | U19: 0 | V19: 164 | W19: 11080 | X19: 1621 | Y19: 12701 | Z19: 4146 | AA19: 1699
B20: QE1 | C20: NHS Lancashire And South Cumbria Integrated Care Board | D20: 45166 | E20: 0 | F20: 32469 | G20: 77635 | H20: 27622 | I20: 0 | J20: 31048 | K20: 58670 | L20: 17544 | M20: 0 | N20: 1421 | O20: 18965 | P20: 0.75571585 | Q20: 0.61156622 | R20: - | S20: 0.95623518 | T20: 12448 | U20: 0 | V20: 210 | W20: 12658 | X20: 6936 | Y20: 19594 | Z20: 4518 | AA20: 2276
B21: QF7 | C21: NHS South Yorkshire Integrated Care Board | D21: 48559 | E21: 1395 | F21: 12605 | G21: 62559 | H21: 32261 | I21: 1329 | J21: 12229 | K21: 45819 | L21: 16298 | M21: 66 | N21: 376 | O21: 16740 | P21: 0.7324126 | Q21: 0.66436706 | R21: 0.95268817 | S21: 0.97017057 | T21: 13283 | U21: 0 | V21: 341 | W21: 13624 | X21: 5377 | Y21: 19001 | Z21: 4128 | AA21: 510
B22: QGH | C22: NHS Herefordshire And Worcestershire Integrated Care Board | D22: 21120 | E22: 976 | F22: 6546 | G22: 28642 | H22: 11566 | I22: 976 | J22: 6412 | K22: 18954 | L22: 9554 | M22: 0 | N22: 134 | O22: 9688 | P22: 0.66175546 | Q22: 0.54763258 | R22: 1 | S22: 0.97952948 | T22: 4627 | U22: 0 | V22: 0 | W22: 4627 | X22: 980 | Y22: 5607 | Z22: 2402 | AA22: 1197
B23: QHL | C23: NHS Birmingham And Solihull Integrated Care Board | D23: 39277 | E23: 407 | F23: 13556 | G23: 53240 | H23: 23340 | I23: 407 | J23: 13497 | K23: 37244 | L23: 15937 | M23: 0 | N23: 59 | O23: 15996 | P23: 0.69954921 | Q23: 0.5942409 | R23: 1 | S23: 0.99564768 | T23: 10912 | U23: 0 | V23: 0 | W23: 10912 | X23: 8759 | Y23: 19671 | Z23: 3795 | AA23: 2088
B24: QHM | C24: NHS North East And North Cumbria Integrated Care Board | D24: 76594 | E24: 3327 | F24: 73483 | G24: 153404 | H24: 44504 | I24: 3183 | J24: 72354 | K24: 120041 | L24: 32090 | M24: 144 | N24: 1129 | O24: 33363 | P24: 0.78251545 | Q24: 0.58103768 | R24: 0.95671776 | S24: 0.9846359 | T24: 25489 | U24: 44 | V24: 712 | W24: 26245 | X24: 10995 | Y24: 37240 | Z24: 4613 | AA24: 354
B25: QJ2 | C25: NHS Derby And Derbyshire Integrated Care Board | D25: 29713 | E25: 0 | F25: 24894 | G25: 54607 | H25: 15841 | I25: 0 | J25: 24328 | K25: 40169 | L25: 13872 | M25: 0 | N25: 566 | O25: 14438 | P25: 0.73560166 | Q25: 0.53313365 | R25: - | S25: 0.9772636 | T25: 5973 | U25: 0 | V25: 22 | W25: 5995 | X25: 2902 | Y25: 8897 | Z25: 2598 | AA25: 974
B26: QJK | C26: NHS Devon Integrated Care Board | D26: 31228 | E26: 74 | F26: 18975 | G26: 50277 | H26: 15105 | I26: 68 | J26: 18457 | K26: 33630 | L26: 16123 | M26: 6 | N26: 518 | O26: 16647 | P26: 0.66889433 | Q26: 0.48370053 | R26: 0.91891892 | S26: 0.97270092 | T26: 7028 | U26: 0 | V26: 34 | W26: 7062 | X26: 3183 | Y26: 10245 | Z26: 3695 | AA26: 968
B27: QJM | C27: NHS Lincolnshire Integrated Care Board | D27: 17584 | E27: 0 | F27: 14647 | G27: 32231 | H27: 11191 | I27: 0 | J27: 13924 | K27: 25115 | L27: 6393 | M27: 0 | N27: 723 | O27: 7116 | P27: 0.77921876 | Q27: 0.63643085 | R27: - | S27: 0.95063836 | T27: 4773 | U27: 0 | V27: 0 | W27: 4773 | X27: 1212 | Y27: 5985 | Z27: 1975 | AA27: 1347
B28: QK1 | C28: NHS Leicester, Leicestershire And Rutland Integrated Care Board | D28: 24152 | E28: 2198 | F28: 16850 | G28: 43200 | H28: 14347 | I28: 2012 | J28: 16797 | K28: 33156 | L28: 9805 | M28: 186 | N28: 53 | O28: 10044 | P28: 0.7675 | Q28: 0.59402948 | R28: 0.91537762 | S28: 0.9968546 | T28: 6766 | U28: 5 | V28: 0 | W28: 6771 | X28: 3841 | Y28: 10612 | Z28: 1639 | AA28: 499
B29: QKK | C29: NHS South East London Integrated Care Board | D29: 43742 | E29: 0 | F29: 39380 | G29: 83122 | H29: 22411 | I29: 0 | J29: 38021 | K29: 60432 | L29: 21331 | M29: 0 | N29: 1359 | O29: 22690 | P29: 0.72702774 | Q29: 0.51234511 | R29: - | S29: 0.9654901 | T29: 10277 | U29: 0 | V29: 0 | W29: 10277 | X29: 1243 | Y29: 11520 | Z29: 4482 | AA29: 1478
B30: QKS | C30: NHS Kent And Medway Integrated Care Board | D30: 58343 | E30: 0 | F30: 43108 | G30: 101451 | H30: 39373 | I30: 0 | J30: 41084 | K30: 80457 | L30: 18970 | M30: 0 | N30: 2024 | O30: 20994 | P30: 0.79306266 | Q30: 0.67485388 | R30: - | S30: 0.95304816 | T30: 10889 | U30: 0 | V30: 528 | W30: 11417 | X30: 2034 | Y30: 13451 | Z30: 4876 | AA30: 2668
B31: QMF | C31: NHS North East London Integrated Care Board | D31: 53046 | E31: 3366 | F31: 41981 | G31: 98393 | H31: 34628 | I31: 3106 | J31: 39921 | K31: 77655 | L31: 18418 | M31: 260 | N31: 2060 | O31: 20738 | P31: 0.78923297 | Q31: 0.65279192 | R31: 0.92275698 | S31: 0.95093018 | T31: 9346 | U31: 0 | V31: 24 | W31: 9370 | X31: 4134 | Y31: 13504 | Z31: 3429 | AA31: 1801
B32: QNC | C32: NHS Staffordshire And Stoke-On-Trent Integrated Care Board | D32: 15769 | E32: 540 | F32: 9723 | G32: 26032 | H32: 7131 | I32: 540 | J32: 9520 | K32: 17191 | L32: 8638 | M32: 0 | N32: 203 | O32: 8841 | P32: 0.66037953 | Q32: 0.45221637 | R32: 1 | S32: 0.97912167 | T32: 4724 | U32: 0 | V32: 0 | W32: 4724 | X32: 1167 | Y32: 5891 | Z32: 1772 | AA32: 640
B33: QOC | C33: NHS Shropshire, Telford And Wrekin Integrated Care Board | D33: 11747 | E33: 0 | F33: 6204 | G33: 17951 | H33: 5069 | I33: 0 | J33: 5843 | K33: 10912 | L33: 6678 | M33: 0 | N33: 361 | O33: 7039 | P33: 0.607877 | Q33: 0.43151443 | R33: - | S33: 0.94181173 | T33: 3708 | U33: 0 | V33: 209 | W33: 3917 | X33: 2134 | Y33: 6051 | Z33: 1912 | AA33: 1373
B34: QOP | C34: NHS Greater Manchester Integrated Care Board | D34: 92773 | E34: 3914 | F34: 36006 | G34: 132693 | H34: 53232 | I34: 3566 | J34: 34752 | K34: 91550 | L34: 39541 | M34: 348 | N34: 1254 | O34: 41143 | P34: 0.68993843 | Q34: 0.57378763 | R34: 0.9110884 | S34: 0.96517247 | T34: 22436 | U34: 110 | V34: 760 | W34: 23306 | X34: 6451 | Y34: 29757 | Z34: 9120 | AA34: 2911
B35: QOQ | C35: NHS Humber And North Yorkshire Integrated Care Board | D35: 39069 | E35: 34 | F35: 28840 | G35: 67943 | H35: 19451 | I35: 34 | J35: 26842 | K35: 46327 | L35: 19618 | M35: 0 | N35: 1998 | O35: 21616 | P35: 0.68185096 | Q35: 0.49786276 | R35: 1 | S35: 0.93072122 | T35: 13829 | U35: 0 | V35: 0 | W35: 13829 | X35: 3427 | Y35: 17256 | Z35: 3873 | AA35: 1685
B36: QOX | C36: NHS Bath And North East Somerset, Swindon And Wiltshire Integrated Care Board | D36: 22499 | E36: 339 | F36: 11521 | G36: 34359 | H36: 12191 | I36: 339 | J36: 10840 | K36: 23370 | L36: 10308 | M36: 0 | N36: 681 | O36: 10989 | P36: 0.68017113 | Q36: 0.5418463 | R36: 1 | S36: 0.94089055 | T36: 6801 | U36: 0 | V36: 0 | W36: 6801 | X36: 4208 | Y36: 11009 | Z36: 2922 | AA36: 851
B37: QPM | C37: NHS Northamptonshire Integrated Care Board | D37: 20639 | E37: 654 | F37: 12964 | G37: 34257 | H37: 12037 | I37: 629 | J37: 12863 | K37: 25529 | L37: 8602 | M37: 25 | N37: 101 | O37: 8728 | P37: 0.74521996 | Q37: 0.58321624 | R37: 0.9617737 | S37: 0.99220919 | T37: 4376 | U37: 0 | V37: 0 | W37: 4376 | X37: 559 | Y37: 4935 | Z37: 2563 | AA37: 1564
B38: QR1 | C38: NHS Gloucestershire Integrated Care Board | D38: 14773 | E38: 0 | F38: 9047 | G38: 23820 | H38: 9134 | I38: 0 | J38: 8722 | K38: 17856 | L38: 5639 | M38: 0 | N38: 325 | O38: 5964 | P38: 0.74962217 | Q38: 0.61829012 | R38: - | S38: 0.96407649 | T38: 2579 | U38: 0 | V38: 0 | W38: 2579 | X38: 2907 | Y38: 5486 | Z38: 808 | AA38: 454
B39: QRL | C39: NHS Hampshire And Isle Of Wight Integrated Care Board | D39: 40638 | E39: 2670 | F39: 28419 | G39: 71727 | H39: 24750 | I39: 2631 | J39: 27307 | K39: 54688 | L39: 15888 | M39: 39 | N39: 1112 | O39: 17039 | P39: 0.7624465 | Q39: 0.60903588 | R39: 0.98539326 | S39: 0.96087125 | T39: 11993 | U39: 11 | V39: 23 | W39: 12027 | X39: 5444 | Y39: 17471 | Z39: 2929 | AA39: 1337
B40: QSL | C40: NHS Somerset Integrated Care Board | D40: 12302 | E40: 0 | F40: 9553 | G40: 21855 | H40: 6447 | I40: 0 | J40: 9229 | K40: 15676 | L40: 5855 | M40: 0 | N40: 324 | O40: 6179 | P40: 0.71727294 | Q40: 0.52406113 | R40: - | S40: 0.96608395 | T40: 3121 | U40: 0 | V40: 0 | W40: 3121 | X40: 1809 | Y40: 4930 | Z40: 639 | AA40: 86
B41: QT1 | C41: NHS Nottingham And Nottinghamshire Integrated Care Board | D41: 24921 | E41: 2016 | F41: 18044 | G41: 44981 | H41: 13818 | I41: 1933 | J41: 15439 | K41: 31190 | L41: 11103 | M41: 83 | N41: 2605 | O41: 13791 | P41: 0.69340388 | Q41: 0.55447213 | R41: 0.95882937 | S41: 0.85563068 | T41: 7619 | U41: 0 | V41: 1292 | W41: 8911 | X41: 4341 | Y41: 13252 | Z41: 1886 | AA41: 1158
B42: QT6 | C42: NHS Cornwall And The Isles Of Scilly Integrated Care Board | D42: 7435 | E42: 0 | F42: 12254 | G42: 19689 | H42: 3507 | I42: 0 | J42: 11352 | K42: 14859 | L42: 3928 | M42: 0 | N42: 902 | O42: 4830 | P42: 0.75468536 | Q42: 0.47168796 | R42: - | S42: 0.92639138 | T42: 2487 | U42: 0 | V42: 59 | W42: 2546 | X42: 1459 | Y42: 4005 | Z42: 944 | AA42: 497
B43: QUA | C43: NHS Black Country Integrated Care Board | D43: 45184 | E43: 2914 | F43: 24606 | G43: 72704 | H43: 29635 | I43: 2612 | J43: 24056 | K43: 56303 | L43: 15549 | M43: 302 | N43: 550 | O43: 16401 | P43: 0.77441406 | Q43: 0.65587376 | R43: 0.89636239 | S43: 0.97764773 | T43: 17140 | U43: 0 | V43: 70 | W43: 17210 | X43: 4311 | Y43: 21521 | Z43: 5040 | AA43: 1221
B44: QUY | C44: NHS Bristol, North Somerset And South Gloucestershire Integrated Care Board | D44: 26019 | E44: 2648 | F44: 9915 | G44: 38582 | H44: 17631 | I44: 2342 | J44: 9360 | K44: 29333 | L44: 8388 | M44: 306 | N44: 555 | O44: 9249 | P44: 0.76027681 | Q44: 0.6776202 | R44: 0.88444109 | S44: 0.94402421 | T44: 8606 | U44: 20 | V44: 0 | W44: 8626 | X44: 4081 | Y44: 12707 | Z44: 1915 | AA44: 620
B45: QVV | C45: NHS Dorset Integrated Care Board | D45: 21656 | E45: 0 | F45: 8519 | G45: 30175 | H45: 13819 | I45: 0 | J45: 8513 | K45: 22332 | L45: 7837 | M45: 0 | N45: 6 | O45: 7843 | P45: 0.74008285 | Q45: 0.63811415 | R45: - | S45: 0.99929569 | T45: 6313 | U45: 2 | V45: 0 | W45: 6315 | X45: 3120 | Y45: 9435 | Z45: 1611 | AA45: 412
...

Sheet System Mapping
A3: Org code | B3: Region | C3: Name | D3: STP | G3: STP | H3: Code
A4: RC9 | B4: East of England Commissioning Region | C4: Bedfordshire Hospitals NHS Foundation Trust | D4: NHS Central East Integrated Care Board | G4: Bath and North East Somerset, Swindon and Wiltshire STP | H4: QOX | I4: NHS BATH AND NORTH EAST SOMERSET, SWINDON AND WILTSHIRE INTEGRATED CARE BOARD | J4: NHS Bath And North East Somerset, Swindon And Wiltshire Integrated Care Board
A5: RD8 | B5: East of England Commissioning Region | C5: Milton Keynes University Hospital NHS Foundation Trust | D5: NHS Central East Integrated Care Board | G5: Bedfordshire, Luton and Milton Keynes STP | H5: QHG | I5: NHS BEDFORDSHIRE, LUTON AND MILTON KEYNES INTEGRATED CARE BOARD | J5: NHS Bedfordshire, Luton And Milton Keynes Integrated Care Board
A6: Y02428 | B6: East of England Commissioning Region | C6: Putnoe Medical Centre Walk In Centre | D6: NHS Central East Integrated Care Board | G6: Birmingham and Solihull STP | H6: QHL | I6: NHS BIRMINGHAM AND SOLIHULL INTEGRATED CARE BOARD | J6: NHS Birmingham And Solihull Integrated Care Board
A7: RGT | B7: East of England Commissioning Region | C7: Cambridge University Hospitals NHS Foundation Trust | D7: NHS Central East Integrated Care Board | G7: Bristol, North Somerset and South Gloucestershire STP | H7: QUY | I7: NHS BRISTOL, NORTH SOMERSET AND SOUTH GLOUCESTERSHIRE INTEGRATED CARE BOARD | J7: NHS Bristol, North Somerset And South Gloucestershire Integrated Care Board
A8: RGN | B8: East of England Commissioning Region | C8: North West Anglia NHS Foundation Trust | D8: NHS Central East Integrated Care Board | G8: Buckinghamshire, Oxfordshire and Berkshire West STP | H8: QU9 | I8: NHS BUCKINGHAMSHIRE, OXFORDSHIRE AND BERKSHIRE WEST INTEGRATED CARE BOARD | J8: NHS Buckinghamshire, Oxfordshire And Berkshire West Integrated Care Board
A9: RWH | B9: East of England Commissioning Region | C9: East And North Hertfordshire NHS Trust | D9: NHS Central East Integrated Care Board | G9: Cambridgeshire and Peterborough STP | H9: QUE | I9: NHS CAMBRIDGESHIRE AND PETERBOROUGH INTEGRATED CARE BOARD | J9: NHS Cambridgeshire And Peterborough Integrated Care Board
A10: RY4 | B10: East of England Commissioning Region | C10: Hertfordshire Community NHS Trust | D10: NHS Central East Integrated Care Board | G10: Cheshire and Merseyside STP | H10: QYG | I10: NHS CHESHIRE AND MERSEYSIDE INTEGRATED CARE BOARD | J10: NHS Cheshire And Merseyside Integrated Care Board
A11: DT301 | B11: East of England Commissioning Region | C11: Herts Urgent Care (Ascots Lane) | D11: NHS Central East Integrated Care Board | G11: Cornwall and The Isles of Scilly Health & Social Care Partnership (STP) | H11: QT6 | I11: NHS CORNWALL AND THE ISLES OF SCILLY INTEGRATED CARE BOARD | J11: NHS Cornwall And The Isles Of Scilly Integrated Care Board
A12: RQW | B12: East of England Commissioning Region | C12: The Princess Alexandra Hospital NHS Trust | D12: NHS Essex Integrated Care Board | G12: Coventry and Warwickshire STP | H12: QWU | I12: NHS COVENTRY AND WARWICKSHIRE INTEGRATED CARE BOARD | J12: NHS Coventry And Warwickshire Integrated Care Board
A13: RWG | B13: East of England Commissioning Region | C13: West Hertfordshire Teaching Hospitals NHS Trust | D13: NHS Central East Integrated Care Board | G13: Cumbria and North East STP | H13: QHM | I13: NHS NORTH EAST AND NORTH CUMBRIA INTEGRATED CARE BOARD | J13: NHS North East And North Cumbria Integrated Care Board
A14: RAJ | B14: East of England Commissioning Region | C14: Mid And South Essex NHS Foundation Trust | D14: NHS Essex Integrated Care Board | G14: Devon STP | H14: QJK | I14: NHS DEVON INTEGRATED CARE BOARD | J14: NHS Devon Integrated Care Board
A15: RGP | B15: East of England Commissioning Region | C15: James Paget University Hospitals NHS Foundation Trust | D15: NHS Norfolk and Suffolk Integrated Care Board | G15: Dorset STP | H15: QVV | I15: NHS DORSET INTEGRATED CARE BOARD | J15: NHS Dorset Integrated Care Board
... A45: RJ7 | B45: London Commissioning Region | C45: St George's University Hospitals NHS Foundation Trust | D45: NHS South West London Integrated Care Board | G45: West Yorkshire (Health & Care Partnership) STP | H45: QWO | I45: NHS WEST YORKSHIRE INTEGRATED CARE BOARD | J45: NHS West Yorkshire Integrated Care Board
A46: RQ3 | B46: Midlands Commissioning Region | C46: Birmingham Women's And Children's NHS Foundation Trust | D46: NHS Birmingham And Solihull Integrated Care Board
A47: RRK | B47: Midlands Commissioning Region | C47: University Hospitals Birmingham NHS Foundation Trust | D47: NHS Birmingham And Solihull Integrated Care Board
A48: RXK | B48: Midlands Commissioning Region | C48: Sandwell And West Birmingham Hospitals NHS Trust | D48: NHS Black Country Integrated Care Board
A49: RNA | B49: Midlands Commissioning Region | C49: The Dudley Group NHS Foundation Trust | D49: NHS Black Country Integrated Care Board
A50: RL4 | B50: Midlands Commissioning Region | C50: The Royal Wolverhampton NHS Trust | D50: NHS Black Country Integrated Care Board
A51: RBK | B51: Midlands Commissioning Region | C51: Walsall Healthcare NHS Trust | D51: NHS Black Country Integrated Care Board
A52: RYG | B52: Midlands Commissioning Region | C52: Coventry and Warwickshire Partnership NHS Trust | D52: NHS Coventry And Warwickshire Integrated Care Board
A53: RLT | B53: Midlands Commissioning Region | C53: George Eliot Hospital NHS Trust | D53: NHS Coventry And Warwickshire Integrated Care Board
A54: RJC | B54: Midlands Commissioning Region | C54: South Warwickshire University NHS Foundation Trust | D54: NHS Coventry And Warwickshire Integrated Care Board
A55: RKB | B55: Midlands Commissioning Region | C55: University Hospitals Coventry And Warwickshire NHS Trust | D55: NHS Coventry And Warwickshire Integrated Care Board
A56: RFS | B56: Midlands Commissioning Region | C56: Chesterfield Royal Hospital NHS Foundation Trust | D56: NHS Derby And Derbyshire Integrated Care Board
A57: RTG | B57: Midlands Commissioning Region | C57: University Hospitals Of Derby And Burton NHS Foundation Trust | D57: NHS Derby And Derbyshire Integrated Care Board
... A270: Y02816 | B270: South East Commissioning Region | C270: Eastbourne Station Health Centre | D270: NHS Sussex Integrated Care Board

Sheet Provider Level Data
E1: 4 | F1: 5 | G1: 6 | M1: 10 | N1: 11 | O1: 12 | U1: 18 | V1: 19 | W1: 20 | Y1: 21 | AA1: 16 | AB1: 17
B2: Title: | C2: A&E Attendances & Emergency Admission monthly statistics, NHS and independent sector organisations in England | E2: 7 | F2: 8 | G2: 9 | M2: 13 | N2: 14 | O2: 15
B4: Summary: | C4: The total of booked and non-booked A&E attendances, as well as emergency admissions and headline 4-hour performance. Please see the Supplementary ECDS Analysis file for further breakdowns of A&E attendance data, this can be found published below this file on the NHS England Website, this provides attendance data split by age groups, gender, ethnicity, chief complaint and provides a data completeness and quality fact sheet.
B6: Period: | C6: September 26
B7: Source: | C7: SDCS data collection - MSitAE
B8: Basis: | C8: Provider
B9: Published: | C9: 8th October 2026
B10: Revised:
B11: Status: | C11: Published
B12: Contact: | C12: Kerry Evert - england.aedata@nhs.net
B14: Provider Level Data
E15: A&E attendances | I15: A&E attendances less than 4 hours from arrival to admission, transfer or discharge | M15: A&E attendances greater than 4 hours from arrival to admission, transfer or discharge | Q15: Percentage of attendances within 4 hours | U15: Emergency Admissions
B16: Code | C16: Region | D16: Name | E16: Type 1 Departments - Major A&E | F16: Type 2 Departments - Single Specialty | G16: Type 3 Departments - Other A&E/Minor Injury Unit | H16: Total attendances | I16: Type 1 Departments - Major A&E | J16: Type 2 Departments - Single Specialty | K16: Type 3 Departments - Other A&E/Minor Injury Unit | L16: Total Attendances < 4 hours | M16: Type 1 Departments - Major A&E | N16: Type 2 Departments - Single Specialty | O16: Type 3 Departments - Other A&E/Minor Injury Unit | P16: Total Attendances > 4 hours | Q16: Percentage in 4 hours or less (all) | R16: Percentage in 4 hours or less (type 1) | S16: Percentage in 4 hours or less (type 2) | T16: Percentage in 4 hours or less (type 3) | U16: Emergency Admissions via Type 1 A&E | V16: Emergency Admissions via Type 2 A&E | W16: Emergency Admissions via Type 3 and 4 A&E | X16: Total Emergency Admissions via A&E | Y16: Other Emergency admissions (i.e not via A&E) | Z16: Total Emergency Admissions | AA16: Number of patients spending >4 hours from decision to admit to admission | AB16: Number of patients spending >12 hours from decision to admit to admission
B17: - | C17: - | D17: England | E17: 1503149 | F17: 55513 | G17: 886081 | H17: 2444743 | I17: 910567 | J17: 52395 | K17: 855030 | L17: 1817992 | M17: 592582 | N17: 3118 | O17: 31051 | P17: 626751 | Q17: 0.74363318 | R17: 0.60577295 | S17: 0.94383298 | T17: 0.96495693 | U17: 394675 | V17: 1534 | W17: 5107 | X17: 401316 | Y17: 134842 | Z17: 536158 | AA17: 129199 | AB17: 50582
B19: RC9 | C19: NHS England East Of England | D19: Bedfordshire Hospitals NHS Foundation Trust | E19: 18509 | F19: 0 | G19: 8667 | H19: 27176 | I19: 11566 | J19: 0 | K19: 8667 | L19: 20233 | M19: 6943 | N19: 0 | O19: 0 | P19: 6943 | Q19: 0.74451722 | R19: 0.62488519 | S19: - | T19: 1 | U19: 5154 | V19: 0 | W19: 0 | X19: 5154 | Y19: 2480 | Z19: 7634 | AA19: 166 | AB19: 85 | AC19: NHS Central East Integrated Care Board
B20: RGT | C20: NHS England East Of England | D20: Cambridge University Hospitals NHS Foundation Trust | E20: 12085 | F20: 0 | G20: 5862 | H20: 17947 | I20: 6528 | J20: 0 | K20: 5762 | L20: 12290 | M20: 5557 | N20: 0 | O20: 100 | P20: 5657 | Q20: 0.68479412 | R20: 0.54017377 | S20: - | T20: 0.98294098 | U20: 3007 | V20: 0 | W20: 35 | X20: 3042 | Y20: 422 | Z20: 3464 | AA20: 784 | AB20: 262 | AC20: NHS Central East Integrated Care Board
B21: RWH | C21: NHS England East Of England | D21: East And North Hertfordshire Teaching NHS Trust | E21: 9588 | F21: 0 | G21: 9229 | H21: 18817 | I21: 4512 | J21: 0 | K21: 9107 | L21: 13619 | M21: 5076 | N21: 0 | O21: 122 | P21: 5198 | Q21: 0.72376043 | R21: 0.47058824 | S21: - | T21: 0.9867808 | U21: 2198 | V21: 0 | W21: 3 | X21: 2201 | Y21: 425 | Z21: 2626 | AA21: 526 | AB21: 89 | AC21: NHS Central East Integrated Care Board
B22: RDE | C22: NHS England East Of England | D22: East Suffolk And North Essex NHS Foundation Trust | E22: 12846 | F22: 0 | G22: 12888 | H22: 25734 | I22: 7552 | J22: 0 | K22: 11936 | L22: 19488 | M22: 5294 | N22: 0 | O22: 952 | P22: 6246 | Q22: 0.75728608 | R22: 0.58788728 | S22: - | T22: 0.92613284 | U22: 5016 | V22: 0 | W22: 1 | X22: 5017 | Y22: 220 | Z22: 5237 | AA22: 1471 | AB22: 858 | AC22: NHS Norfolk and Suffolk Integrated Care Board
B23: RY4 | C23: NHS England East Of England | D23: Hertfordshire Community NHS Trust | E23: 0 | F23: 0 | G23: 1195 | H23: 1195 | I23: 0 | J23: 0 | K23: 1129 | L23: 1129 | M23: 0 | N23: 0 | O23: 66 | P23: 66 | Q23: 0.94476987 | R23: - | S23: - | T23: 0.94476987 | U23: 0 | V23: 0 | W23: 0 | X23: 0 | Y23: 0 | Z23: 0 | AA23: 0 | AB23: 0 | AC23: NHS Central East Integrated Care Board
B24: DT301 | C24: NHS England East Of England | D24: Herts Urgent Care (Ascots Lane) | E24: 0 | F24: 0 | G24: 2328 | H24: 2328 | I24: 0 | J24: 0 | K24: 2208 | L24: 2208 | M24: 0 | N24: 0 | O24: 120 | P24: 120 | Q24: 0.94845361 | R24: - | S24: - | T24: 0.94845361 | U24: 0 | V24: 0 | W24: 0 | X24: 0 | Y24: 0 | Z24: 0 | AA24: 0 | AB24: 0 | AC24: NHS Central East Integrated Care Board
B25: RGP | C25: NHS England East Of England | D25: James Paget University Hospitals NHS Foundation Trust | E25: 7874 | F25: 0 | G25: 1582 | H25: 9456 | I25: 4655 | J25: 0 | K25: 1582 | L25: 6237 | M25: 3219 | N25: 0 | O25: 0 | P25: 3219 | Q25: 0.65958122 | R25: 0.59118618 | S25: - | T25: 1 | U25: 1692 | V25: 0 | W25: 0 | X25: 1692 | Y25: 461 | Z25: 2153 | AA25: 1034 | AB25: 423 | AC25: NHS Norfolk and Suffolk Integrated Care Board
B26: RAJ | C26: NHS England East Of England | D26: Mid And South Essex NHS Foundation Trust | E26: 28628 | F26: 0 | G26: 8515 | H26: 37143 | I26: 17700 | J26: 0 | K26: 8154 | L26: 25854 | M26: 10928 | N26: 0 | O26: 361 | P26: 11289 | Q26: 0.69606655 | R26: 0.61827581 | S26: - | T26: 0.95760423 | U26: 9218 | V26: 0 | W26: 164 | X26: 9382 | Y26: 1161 | Z26: 10543 | AA26: 3299 | AB26: 1371 | AC26: NHS Essex Integrated Care Board
B27: RD8 | C27: NHS England East Of England | D27: Milton Keynes University Hospital NHS Foundation Trust | E27: 9420 | F27: 0 | G27: 6789 | H27: 16209 | I27: 4770 | J27: 0 | K27: 6611 | L27: 11381 | M27: 4650 | N27: 0 | O27: 178 | P27: 4828 | Q27: 0.70214079 | R27: 0.50636943 | S27: - | T27: 0.97378112 | U27: 2624 | V27: 0 | W27: 0 | X27: 2624 | Y27: 424 | Z27: 3048 | AA27: 1105 | AB27: 2 | AC27: NHS Central East Integrated Care Board
B28: RM1 | C28: NHS England East Of England | D28: Norfolk And Norwich University Hospitals NHS Foundation Trust | E28: 13687 | F28: 0 | G28: 8042 | H28: 21729 | I28: 9311 | J28: 0 | K28: 8035 | L28: 17346 | M28: 4376 | N28: 0 | O28: 7 | P28: 4383 | Q28: 0.798288 | R28: 0.68028056 | S28: - | T28: 0.99912957 | U28: 2331 | V28: 0 | W28: 0 | X28: 2331 | Y28: 1562 | Z28: 3893 | AA28: 1052 | AB28: 287 | AC28: NHS Norfolk and Suffolk Integrated Care Board
B29: RGN | C29: NHS England East Of England | D29: North West Anglia NHS Foundation Trust | E29: 17985 | F29: 0 | G29: 3887 | H29: 21872 | I29: 10986 | J29: 0 | K29: 3617 | L29: 14603 | M29: 6999 | N29: 0 | O29: 270 | P29: 7269 | Q29: 0.66765728 | R29: 0.61084237 | S29: - | T29: 0.93053769 | U29: 4078 | V29: 0 | W29: 30 | X29: 4108 | Y29: 1434 | Z29: 5542 | AA29: 1238 | AB29: 705 | AC29: NHS Central East Integrated Care Board
B30: Y02428 | C30: NHS England East Of England | D30: Putnoe Walk In Centre | E30: 0 | F30: 0 | G30: 2335 | H30: 2335 | I30: 0 | J30: 0 | K30: 2335 | L30: 2335 | M30: 0 | N30: 0 | O30: 0 | P30: 0 | Q30: 1 | R30: - | S30: - | T30: 1 | U30: 0 | V30: 0 | W30: 0 | X30: 0 | Y30: 0 | Z30: 0 | AA30: 0 | AB30: 0 | AC30: NHS Central East Integrated Care Board
B31: RQW | C31: NHS England East Of England | D31: The Princess Alexandra Hospital NHS Trust | E31: 9234 | F31: 0 | G31: 2565 | H31: 11799 | I31: 6590 | J31: 0 | K31: 2565 | L31: 9155 | M31: 2644 | N31: 0 | O31: 0 | P31: 2644 | Q31: 0.77591321 | R31: 0.71366688 | S31: - | T31: 1 | U31: 1698 | V31: 0 | W31: 0 | X31: 1698 | Y31: 460 | Z31: 2158 | AA31: 847 | AB31: 328 | AC31: NHS Essex Integrated Care Board
B32: RCX | C32: NHS England East Of England | D32: The Queen Elizabeth Hospital, King's Lynn, NHS Foundation Trust | E32: 6636 | F32: 0 | G32: 1297 | H32: 7933 | I32: 3844 | J32: 0 | K32: 1297 | L32: 5141 | M32: 2792 | N32: 0 | O32: 0 | P32: 2792 | Q32: 0.64805244 | R32: 0.57926462 | S32: - | T32: 1 | U32: 1753 | V32: 0 | W32: 0 | X32: 1753 | Y32: 393 | Z32: 2146 | AA32: 942 | AB32: 154 | AC32: NHS Norfolk and Suffolk Integrated Care Board
B33: RWG | C33: NHS England East Of England | D33: West Hertfordshire Teaching Hospitals NHS Trust | E33: 8453 | F33: 0 | G33: 9787 | H33: 18240 | I33: 6176 | J33: 0 | K33: 9733 | L33: 15909 | M33: 2277 | N33: 0 | O33: 54 | P33: 2331 | Q33: 0.87220395 | R33: 0.73062818 | S33: - | T33: 0.99448248 | U33: 5325 | V33: 0 | W33: 0 | X33: 5325 | Y33: 524 | Z33: 5849 | AA33: 753 | AB33: 15 | AC33: NHS Central East Integrated Care Board
B34: RGR | C34: NHS England East Of England | D34: West Suffolk NHS Foundation Trust | E34: 8324 | F34: 0 | G34: 940 | H34: 9264 | I34: 6633 | J34: 0 | K34: 940 | L34: 7573 | M34: 1691 | N34: 0 | O34: 0 | P34: 1691 | Q34: 0.81746546 | R34: 0.79685247 | S34: - | T34: 1 | U34: 1940 | V34: 0 | W34: 0 | X34: 1940 | Y34: 278 | Z34: 2218 | AA34: 486 | AB34: 149 | AC34: NHS Norfolk and Suffolk Integrated Care Board
B35: G0Q0L | C35: NHS England London | D35: Barking Hospital Utc | E35: 0 | F35: 0 | G35: 2883 | H35: 2883 | I35: 0 | J35: 0 | K35: 2851 | L35: 2851 | M35: 0 | N35: 0 | O35: 32 | P35: 32 | Q35: 0.98890045 | R35: - | S35: - | T35: 0.98890045 | U35: 0 | V35: 0 | W35: 0 | X35: 0 | Y35: 0 | Z35: 0 | AA35: 0 | AB35: 0 | AC35: NHS North East London Integrated Care Board
B36: RF4 | C36: NHS England London | D36: Barking, Havering And Redbridge University Hospitals NHS Trust | E36: 14321 | F36: 2471 | G36: 16018 | H36: 32810 | I36: 9013 | J36: 2212 | K36: 15578 | L36: 26803 | M36: 5308 | N36: 259 | O36: 440 | P36: 6007 | Q36: 0.81691557 | R36: 0.62935549 | S36: 0.89518414 | T36: 0.9725309 | U36: 3593 | V36: 0 | W36: 0 | X36: 3593 | Y36: 2526 | Z36: 6119 | AA36: 1064 | AB36: 568 | AC36: NHS North East London Integrated Care Board
B37: R1H | C37: NHS England London | D37: Barts Health NHS Trust | E37: 27253 | F37: 895 | G37: 18702 | H37: 46850 | I37: 16611 | J37: 894 | K37: 17167 | L37: 34672 | M37: 10642 | N37: 1 | O37: 1535 | P37: 12178 | Q37: 0.74006403 | R37: 0.60951088 | S37: 0.99888268 | T37: 0.91792322 | U37: 3992 | V37: 0 | W37: 24 | X37: 4016 | Y37: 1207 | Z37: 5223 | AA37: 2141 | AB37: 1208 | AC37: NHS North East London Integrated Care Board
B38: AD913 | C38: NHS England London | D38: Beckenham Beacon Ucc | E38: 0 | F38: 0 | G38: 3736 | H38: 3736 | I38: 0 | J38: 0 | K38: 3722 | L38: 3722 | M38: 0 | N38: 0 | O38: 14 | P38: 14 | Q38: 0.99625268 | R38: - | S38: - | T38: 0.99625268 | U38: 0 | V38: 0 | W38: 0 | X38: 0 | Y38: 0 | Z38: 0 | AA38: 0 | AB38: 0 | AC38: NHS South East London Integrated Care Board
B39: RYX | C39: NHS England London | D39: Central London Community Healthcare NHS Trust | E39: 0 | F39: 0 | G39: 14327 | H39: 14327 | I39: 0 | J39: 0 | K39: 13935 | L39: 13935 | M39: 0 | N39: 0 | O39: 392 | P39: 392 | Q39: 0.97263907 | R39: - | S39: - | T39: 0.97263907 | U39: 0 | V39: 0 | W39: 0 | X39: 0 | Y39: 0 | Z39: 0 | AA39: 0 | AB39: 0 | AC39: NHS West and North London Integrated Care Board
B40: RQM | C40: NHS England London | D40: Chelsea And Westminster Hospital NHS Foundation Trust | E40: 21929 | F40: 0 | G40: 6840 | H40: 28769 | I40: 15910 | J40: 0 | K40: 6520 | L40: 22430 | M40: 6019 | N40: 0 | O40: 320 | P40: 6339 | Q40: 0.77965866 | R40: 0.72552328 | S40: - | T40: 0.95321637 | U40: 2966 | V40: 0 | W40: 0 | X40: 2966 | Y40: 316 | Z40: 3282 | AA40: 973 | AB40: 44 | AC40: NHS West and North London Integrated Care Board
B41: RJ6 | C41: NHS England London | D41: Croydon Health Services NHS Trust | E41: 13804 | F41: 0 | G41: 4657 | H41: 18461 | I41: 8710 | J41: 0 | K41: 4657 | L41: 13367 | M41: 5094 | N41: 0 | O41: 0 | P41: 5094 | Q41: 0.72406695 | R41: 0.63097653 | S41: - | T41: 1 | U41: 1090 | V41: 0 | W41: 0 | X41: 1090 | Y41: 150 | Z41: 1240 | AA41: 927 | AB41: 626 | AC41: NHS South West London Integrated Care Board
B42: RVR | C42: NHS England London | D42: Epsom And St Helier University Hospitals NHS Trust | E42: 11638 | F42: 0 | G42: 2921 | H42: 14559 | I42: 7829 | J42: 0 | K42: 2485 | L42: 10314 | M42: 3809 | N42: 0 | O42: 436 | P42: 4245 | Q42: 0.70842778 | R42: 0.67271009 | S42: - | T42: 0.85073605 | U42: 2097 | V42: 0 | W42: 0 | X42: 2097 | Y42: 163 | Z42: 2260 | AA42: 1391 | AB42: 743 | AC42: NHS South West London Integrated Care Board
B43: RJ1 | C43: NHS England London | D43: Guy's And St Thomas' NHS Foundation Trust | E43: 11004 | F43: 0 | G43: 7279 | H43: 18283 | I43: 6731 | J43: 0 | K43: 7062 | L43: 13793 | M43: 4273 | N43: 0 | O43: 217 | P43: 4490 | Q43: 0.75441667 | R43: 0.61168666 | S43: - | T43: 0.97018821 | U43: 2076 | V43: 0 | W43: 0 | X43: 2076 | Y43: 342 | Z43: 2418 | AA43: 232 | AB43: 73 | AC43: NHS South East London Integrated Care Board
B44: K6K0R | C44: NHS England London | D44: Harold Wood Polyclinic Utc | E44: 0 | F44: 0 | G44: 2752 | H44: 2752 | I44: 0 | J44: 0 | K44: 2727 | L44: 2727 | M44: 0 | N44: 0 | O44: 25 | P44: 25 | Q44: 0.9909157 | R44: - | S44: - | T44: 0.9909157 | U44: 0 | V44: 0 | W44: 0 | X44: 0 | Y44: 0 | Z44: 0 | AA44: 0 | AB44: 0 | AC44: NHS North East London Integrated Care Board
...

Sheet Pivot_Kent
A1: ICB | B1: NHS Kent And Medway Integrated Care Board
B3: Data
A4: Provider | B4: Sum of T1_Att | C4: Sum of T1_WithIn4 | D4: Sum of Total_Att | E4: Sum of Total _WithIn4 | F4: Sum of Type1_pct | G4: Sum of All_pct
A5: Dartford And Gravesham NHS Trust | B5: 12375 | C5: 9198 | D5: 16496 | E5: 13221 | F5: 0.74327273 | G5: 0.80146702
A6: Maidstone And Tunbridge Wells NHS Trust | B6: 21697 | C6: 15826 | D6: 23409 | E6: 17537 | F6: 0.7294096 | G6: 0.74915631
A7: Medway NHS Foundation Trust | B7: 10582 | C7: 7375 | D7: 17283 | E7: 13060 | F7: 0.6969382 | G7: 0.75565585
A8: East Kent Hospitals University NHS Foundation Trust | B8: 13689 | C8: 6974 | D8: 26960 | E8: 19431 | F8: 0.50946015 | G8: 0.72073442
A9: Grand total covers the four providers with Type 1 departments only. | B9: 58343 | C9: 39373 | D9: 84148 | E9: 63249 | F9: 0.67485388 | G9: 0.75163997
A13: Provider | B13: Type 1 4-hour%
A14: Dartford and Gravesham | B14: 0.74327273
A15: Maidstone and Tunbridge Wells (MTW) | B15: 0.7294096
A16: Medway | B16: 0.6969382
A17: East Kent | B17: 0.50946015
A60: Conclusion
A61: 1. Maidstone and Tunbridge Wells NHS Trust (MTW) saw 72.9% of Type 1 A&E attendances within four hours in September 2026.
A62: 2. That put MTW second of the four Kent and Medway acute trusts, behind Dartford and Gravesham (74.3%) and ahead of Medway (69.7%) and East Kent (50.9%).
A63: 3. It is worthy of note that this is a single month and covers Type 1 departments only, so it shows a snapshot, not a trend.
A65: Source: NHS England, Monthly A&E Attendances and Emergency Admissions, September 2026 (published 8 October 2026).

Sheet AE_Clean
A1: Code | B1: Region | C1: Provider | D1: T1_Att | E1: T2_Att | F1: T3_Att | G1: Total_Att | H1: T1_WithIn4 | I1: T2_WithIn4 | J1: T3_WithIn4 | K1: Total _WithIn4 | L1: AllTypes_4hr_pct | M1: Type1_4hr_pct | N1: ICB
A2: RC9 | B2: NHS England East Of England | C2: Bedfordshire Hospitals NHS Foundation Trust | D2: 18509 | E2: 0 | F2: 8667 | G2: 27176 | H2: 11566 | I2: 0 | J2: 8667 | K2: 20233 | L2: =IFERROR(K2/G2, "Missing Data") -> 0.74451722 | M2: =IFERROR(IF(D2=0,"",H2/D2), "Missing Data") -> 0.62488519 | N2: =_xlfn.XLOOKUP(AE[[#This Row],[Code]], 'System Mapping'!$A:$A, 'System Mapping'!$D:$D, "Not Found") -> NHS Central East Integrated Care Board
A3: RGT | B3: NHS England East Of England | C3: Cambridge University Hospitals NHS Foundation Trust | D3: 12085 | E3: 0 | F3: 5862 | G3: 17947 | H3: 6528 | I3: 0 | J3: 5762 | K3: 12290 | L3: =IFERROR(K3/G3, "Missing Data") -> 0.68479412 | M3: =IFERROR(IF(D3=0,"",H3/D3), "Missing Data") -> 0.54017377 | N3: =_xlfn.XLOOKUP(AE[[#This Row],[Code]], 'System Mapping'!$A:$A, 'System Mapping'!$D:$D, "Not Found") -> NHS Central East Integrated Care Board
A4: RWH | B4: NHS England East Of England | C4: East And North Hertfordshire Teaching NHS Trust | D4: 9588 | E4: 0 | F4: 9229 | G4: 18817 | H4: 4512 | I4: 0 | J4: 9107 | K4: 13619 | L4: =IFERROR(K4/G4, "Missing Data") -> 0.72376043 | M4: =IFERROR(IF(D4=0,"",H4/D4), "Missing Data") -> 0.47058824 | N4: =_xlfn.XLOOKUP(AE[[#This Row],[Code]], 'System Mapping'!$A:$A, 'System Mapping'!$D:$D, "Not Found") -> NHS Central East Integrated Care Board
A5: RDE | B5: NHS England East Of England | C5: East Suffolk And North Essex NHS Foundation Trust | D5: 12846 | E5: 0 | F5: 12888 | G5: 25734 | H5: 7552 | I5: 0 | J5: 11936 | K5: 19488 | L5: =IFERROR(K5/G5, "Missing Data") -> 0.75728608 | M5: =IFERROR(IF(D5=0,"",H5/D5), "Missing Data") -> 0.58788728 | N5: =_xlfn.XLOOKUP(AE[[#This Row],[Code]], 'System Mapping'!$A:$A, 'System Mapping'!$D:$D, "Not Found") -> NHS Norfolk and Suffolk Integrated Care Board
A6: RY4 | B6: NHS England East Of England | C6: Hertfordshire Community NHS Trust | D6: 0 | E6: 0 | F6: 1195 | G6: 1195 | H6: 0 | I6: 0 | J6: 1129 | K6: 1129 | L6: =IFERROR(K6/G6, "Missing Data") -> 0.94476987 | M6: =IFERROR(IF(D6=0,"",H6/D6), "Missing Data") | N6: =_xlfn.XLOOKUP(AE[[#This Row],[Code]], 'System Mapping'!$A:$A, 'System Mapping'!$D:$D, "Not Found") -> NHS Central East Integrated Care Board
A7: DT301 | B7: NHS England East Of England | C7: Herts Urgent Care (Ascots Lane) | D7: 0 | E7: 0 | F7: 2328 | G7: 2328 | H7: 0 | I7: 0 | J7: 2208 | K7: 2208 | L7: =IFERROR(K7/G7, "Missing Data") -> 0.94845361 | M7: =IFERROR(IF(D7=0,"",H7/D7), "Missing Data") | N7: =_xlfn.XLOOKUP(AE[[#This Row],[Code]], 'System Mapping'!$A:$A, 'System Mapping'!$D:$D, "Not Found") -> NHS Central East Integrated Care Board
A8: RGP | B8: NHS England East Of England | C8: James Paget University Hospitals NHS Foundation Trust | D8: 7874 | E8: 0 | F8: 1582 | G8: 9456 | H8: 4655 | I8: 0 | J8: 1582 | K8: 6237 | L8: =IFERROR(K8/G8, "Missing Data") -> 0.65958122 | M8: =IFERROR(IF(D8=0,"",H8/D8), "Missing Data") -> 0.59118618 | N8: =_xlfn.XLOOKUP(AE[[#This Row],[Code]], 'System Mapping'!$A:$A, 'System Mapping'!$D:$D, "Not Found") -> NHS Norfolk and Suffolk Integrated Care Board
A9: RAJ | B9: NHS England East Of England | C9: Mid And South Essex NHS Foundation Trust | D9: 28628 | E9: 0 | F9: 8515 | G9: 37143 | H9: 17700 | I9: 0 | J9: 8154 | K9: 25854 | L9: =IFERROR(K9/G9, "Missing Data") -> 0.69606655 | M9: =IFERROR(IF(D9=0,"",H9/D9), "Missing Data") -> 0.61827581 | N9: =_xlfn.XLOOKUP(AE[[#This Row],[Code]], 'System Mapping'!$A:$A, 'System Mapping'!$D:$D, "Not Found") -> NHS Essex Integrated Care Board
A10: RD8 | B10: NHS England East Of England | C10: Milton Keynes University Hospital NHS Foundation Trust | D10: 9420 | E10: 0 | F10: 6789 | G10: 16209 | H10: 4770 | I10: 0 | J10: 6611 | K10: 11381 | L10: =IFERROR(K10/G10, "Missing Data") -> 0.70214079 | M10: =IFERROR(IF(D10=0,"",H10/D10), "Missing Data") -> 0.50636943 | N10: =_xlfn.XLOOKUP(AE[[#This Row],[Code]], 'System Mapping'!$A:$A, 'System Mapping'!$D:$D, "Not Found") -> NHS Central East Integrated Care Board
A11: RM1 | B11: NHS England East Of England | C11: Norfolk And Norwich University Hospitals NHS Foundation Trust | D11: 13687 | E11: 0 | F11: 8042 | G11: 21729 | H11: 9311 | I11: 0 | J11: 8035 | K11: 17346 | L11: =IFERROR(K11/G11, "Missing Data") -> 0.798288 | M11: =IFERROR(IF(D11=0,"",H11/D11), "Missing Data") -> 0.68028056 | N11: =_xlfn.XLOOKUP(AE[[#This Row],[Code]], 'System Mapping'!$A:$A, 'System Mapping'!$D:$D, "Not Found") -> NHS Norfolk and Suffolk Integrated Care Board
A12: RGN | B12: NHS England East Of England | C12: North West Anglia NHS Foundation Trust | D12: 17985 | E12: 0 | F12: 3887 | G12: 21872 | H12: 10986 | I12: 0 | J12: 3617 | K12: 14603 | L12: =IFERROR(K12/G12, "Missing Data") -> 0.66765728 | M12: =IFERROR(IF(D12=0,"",H12/D12), "Missing Data") -> 0.61084237 | N12: =_xlfn.XLOOKUP(AE[[#This Row],[Code]], 'System Mapping'!$A:$A, 'System Mapping'!$D:$D, "Not Found") -> NHS Central East Integrated Care Board
A13: Y02428 | B13: NHS England East Of England | C13: Putnoe Walk In Centre | D13: 0 | E13: 0 | F13: 2335 | G13: 2335 | H13: 0 | I13: 0 | J13: 2335 | K13: 2335 | L13: =IFERROR(K13/G13, "Missing Data") -> 1 | M13: =IFERROR(IF(D13=0,"",H13/D13), "Missing Data") | N13: =_xlfn.XLOOKUP(AE[[#This Row],[Code]], 'System Mapping'!$A:$A, 'System Mapping'!$D:$D, "Not Found") -> NHS Central East Integrated Care Board
... A192: RK9 | B192: NHS England South West | C192: University Hospitals Plymouth NHS Trust | D192: 9089 | E192: 74 | F192: 8290 | G192: 17453 | H192: 3293 | I192: 68 | J192: 8089 | K192: 11450 | L192: =IFERROR(K192/G192, "Missing Data") -> 0.65604767 | M192: =IFERROR(IF(D192=0,"",H192/D192), "Missing Data") -> 0.36230608 | N192: =_xlfn.XLOOKUP(AE[[#This Row],[Code]], 'System Mapping'!$A:$A, 'System Mapping'!$D:$D, "Not Found") -> NHS Devon Integrated Care Board
G193: =SUM(G2:G192) -> 2444743

Sheet Summary
A1: Maidstone and Tunbridge Wells: September 2026
A3: ODS Code | B3: rwf
A4: Provider Name | B4: =_xlfn.XLOOKUP($B$3,AE[Code],AE[Provider]) -> Maidstone And Tunbridge Wells NHS Trust
A5: Total attendances | B5: =_xlfn.XLOOKUP($B$3,AE[Code], AE[Total_Att]) -> 23409
A6: Seen Within 4 Hours | B6: =_xlfn.XLOOKUP($B$3, AE[Code],AE[Total _WithIn4]) -> 17537
A7: All-types 4-hour performance | B7: =_xlfn.XLOOKUP($B$3,AE[Code],AE[AllTypes_4hr_pct]) -> 0.74915631
A8: Type 1 attendances | B8: =_xlfn.XLOOKUP($B$3, AE[Code],AE[T1_Att]) -> 21697
A9: Type 1 4-hour performance | B9: =_xlfn.XLOOKUP($B$3, AE[Code],AE[Type1_4hr_pct]) -> 0.7294096
A11: National-all-types performance | B11: =SUM(AE[Total _WithIn4])/SUM(AE[Total_Att]) -> 0.74363318
A12: Total attendance, all providers | B12: =SUM(AE[Total_Att]) -> 2444743

Sheet Non-Booked Data
E1: 4 | F1: 5 | G1: 6 | M1: 10 | N1: 11 | O1: 12 | U1: 18 | V1: 19 | W1: 20 | Y1: 21 | AA1: 16 | AB1: 17
B2: Title: | C2: A&E Attendances & Emergency Admission monthly statistics, NHS and independent sector organisations in England
B4: Summary: | C4: A&E attendances, performance and emergency admission. Please see the Supplementary ECDS Analysis file for further breakdowns of A&E attendance data, this can be found published below this file on the NHS England Website, this provides attendance data split by age groups, gender, ethnicity, chief complaint and provides a data completeness and quality fact sheet.
B6: Period: | C6: September 26
B7: Source: | C7: SDCS data collection - MSitAE
B8: Basis: | C8: Provider
B9: Published: | C9: 8th October 2026
B10: Revised:
B11: Status: | C11: Published
B12: Contact: | C12: Kerry Evert - england.aedata@nhs.net
B14: Provider Level Data
E15: A&E attendances | I15: A&E attendances less than 4 hours from arrival to admission, transfer or discharge | M15: A&E attendances greater than 4 hours from arrival to admission, transfer or discharge | Q15: Percentage of attendances within 4 hours | U15: Emergency Admissions
B16: Code | C16: Region | D16: Name | E16: Type 1 Departments - Major A&E | F16: Type 2 Departments - Single Specialty | G16: Type 3 Departments - Other A&E/Minor Injury Unit | H16: Total attendances | I16: Type 1 Departments - Major A&E | J16: Type 2 Departments - Single Specialty | K16: Type 3 Departments - Other A&E/Minor Injury Unit | L16: Total Attendances < 4 hours | M16: Type 1 Departments - Major A&E | N16: Type 2 Departments - Single Specialty | O16: Type 3 Departments - Other A&E/Minor Injury Unit | P16: Total Attendances > 4 hours | Q16: Percentage in 4 hours or less (all) | R16: Percentage in 4 hours or less (type 1) | S16: Percentage in 4 hours or less (type 2) | T16: Percentage in 4 hours or less (type 3) | U16: Emergency Admissions via Type 1 A&E | V16: Emergency Admissions via Type 2 A&E | W16: Emergency Admissions via Type 3 and 4 A&E | X16: Total Emergency Admissions via A&E | Y16: Other Emergency admissions (i.e not via A&E) | Z16: Total Emergency Admissions | AA16: Number of patients spending >4 hours from decision to admit to admission | AB16: Number of patients spending >12 hours from decision to admit to admission
B17: - | C17: - | D17: England | E17: 1475440 | F17: 55014 | G17: 839337 | H17: 2369791 | I17: 890810 | J17: 51955 | K17: 808867 | L17: 1751632 | M17: 584630 | N17: 3059 | O17: 30470 | P17: 618159 | Q17: 0.73915041 | R17: 0.60375888 | S17: 0.94439597 | T17: 0.96369754 | U17: 394675 | V17: 1534 | W17: 5107 | X17: 401316 | Y17: 134842 | Z17: 536158 | AA17: 129199 | AB17: 50582
B19: RC9 | C19: NHS England East Of England | D19: Bedfordshire Hospitals NHS Foundation Trust | E19: 18509 | F19: 0 | G19: 8667 | H19: 27176 | I19: 11566 | J19: 0 | K19: 8667 | L19: 20233 | M19: 6943 | N19: 0 | O19: 0 | P19: 6943 | Q19: 0.74451722 | R19: 0.62488519 | S19: - | T19: 1 | U19: 5154 | V19: 0 | W19: 0 | X19: 5154 | Y19: 2480 | Z19: 7634 | AA19: 166 | AB19: 85 | AC19: NHS Central East Integrated Care Board
B20: RGT | C20: NHS England East Of England | D20: Cambridge University Hospitals NHS Foundation Trust | E20: 11809 | F20: 0 | G20: 5629 | H20: 17438 | I20: 6325 | J20: 0 | K20: 5538 | L20: 11863 | M20: 5484 | N20: 0 | O20: 91 | P20: 5575 | Q20: 0.68029591 | R20: 0.53560843 | S20: - | T20: 0.98383372 | U20: 3007 | V20: 0 | W20: 35 | X20: 3042 | Y20: 422 | Z20: 3464 | AA20: 784 | AB20: 262 | AC20: NHS Central East Integrated Care Board
B21: RWH | C21: NHS England East Of England | D21: East And North Hertfordshire Teaching NHS Trust | E21: 9588 | F21: 0 | G21: 9229 | H21: 18817 | I21: 4512 | J21: 0 | K21: 9107 | L21: 13619 | M21: 5076 | N21: 0 | O21: 122 | P21: 5198 | Q21: 0.72376043 | R21: 0.47058824 | S21: - | T21: 0.9867808 | U21: 2198 | V21: 0 | W21: 3 | X21: 2201 | Y21: 425 | Z21: 2626 | AA21: 526 | AB21: 89 | AC21: NHS Central East Integrated Care Board
B22: RDE | C22: NHS England East Of England | D22: East Suffolk And North Essex NHS Foundation Trust | E22: 12846 | F22: 0 | G22: 12888 | H22: 25734 | I22: 7552 | J22: 0 | K22: 11936 | L22: 19488 | M22: 5294 | N22: 0 | O22: 952 | P22: 6246 | Q22: 0.75728608 | R22: 0.58788728 | S22: - | T22: 0.92613284 | U22: 5016 | V22: 0 | W22: 1 | X22: 5017 | Y22: 220 | Z22: 5237 | AA22: 1471 | AB22: 858 | AC22: NHS Norfolk and Suffolk Integrated Care Board
B23: RY4 | C23: NHS England East Of England | D23: Hertfordshire Community NHS Trust | E23: 0 | F23: 0 | G23: 1195 | H23: 1195 | I23: 0 | J23: 0 | K23: 1129 | L23: 1129 | M23: 0 | N23: 0 | O23: 66 | P23: 66 | Q23: 0.94476987 | R23: - | S23: - | T23: 0.94476987 | U23: 0 | V23: 0 | W23: 0 | X23: 0 | Y23: 0 | Z23: 0 | AA23: 0 | AB23: 0 | AC23: NHS Central East Integrated Care Board
B24: DT301 | C24: NHS England East Of England | D24: Herts Urgent Care (Ascots Lane) | E24: 0 | F24: 0 | G24: 2328 | H24: 2328 | I24: 0 | J24: 0 | K24: 2208 | L24: 2208 | M24: 0 | N24: 0 | O24: 120 | P24: 120 | Q24: 0.94845361 | R24: - | S24: - | T24: 0.94845361 | U24: 0 | V24: 0 | W24: 0 | X24: 0 | Y24: 0 | Z24: 0 | AA24: 0 | AB24: 0 | AC24: NHS Central East Integrated Care Board
B25: RGP | C25: NHS England East Of England | D25: James Paget University Hospitals NHS Foundation Trust | E25: 7874 | F25: 0 | G25: 1582 | H25: 9456 | I25: 4655 | J25: 0 | K25: 1582 | L25: 6237 | M25: 3219 | N25: 0 | O25: 0 | P25: 3219 | Q25: 0.65958122 | R25: 0.59118618 | S25: - | T25: 1 | U25: 1692 | V25: 0 | W25: 0 | X25: 1692 | Y25: 461 | Z25: 2153 | AA25: 1034 | AB25: 423 | AC25: NHS Norfolk and Suffolk Integrated Care Board
B26: RAJ | C26: NHS England East Of England | D26: Mid And South Essex NHS Foundation Trust | E26: 28595 | F26: 0 | G26: 8495 | H26: 37090 | I26: 17669 | J26: 0 | K26: 8134 | L26: 25803 | M26: 10926 | N26: 0 | O26: 361 | P26: 11287 | Q26: 0.69568617 | R26: 0.61790523 | S26: - | T26: 0.95750441 | U26: 9218 | V26: 0 | W26: 164 | X26: 9382 | Y26: 1161 | Z26: 10543 | AA26: 3299 | AB26: 1371 | AC26: NHS Essex Integrated Care Board
B27: RD8 | C27: NHS England East Of England | D27: Milton Keynes University Hospital NHS Foundation Trust | E27: 8594 | F27: 0 | G27: 5871 | H27: 14465 | I27: 4400 | J27: 0 | K27: 5761 | L27: 10161 | M27: 4194 | N27: 0 | O27: 110 | P27: 4304 | Q27: 0.7024542 | R27: 0.51198511 | S27: - | T27: 0.98126384 | U27: 2624 | V27: 0 | W27: 0 | X27: 2624 | Y27: 424 | Z27: 3048 | AA27: 1105 | AB27: 2 | AC27: NHS Central East Integrated Care Board
B28: RM1 | C28: NHS England East Of England | D28: Norfolk And Norwich University Hospitals NHS Foundation Trust | E28: 13687 | F28: 0 | G28: 8042 | H28: 21729 | I28: 9311 | J28: 0 | K28: 8035 | L28: 17346 | M28: 4376 | N28: 0 | O28: 7 | P28: 4383 | Q28: 0.798288 | R28: 0.68028056 | S28: - | T28: 0.99912957 | U28: 2331 | V28: 0 | W28: 0 | X28: 2331 | Y28: 1562 | Z28: 3893 | AA28: 1052 | AB28: 287 | AC28: NHS Norfolk and Suffolk Integrated Care Board
B29: RGN | C29: NHS England East Of England | D29: North West Anglia NHS Foundation Trust | E29: 17648 | F29: 0 | G29: 3603 | H29: 21251 | I29: 10751 | J29: 0 | K29: 3350 | L29: 14101 | M29: 6897 | N29: 0 | O29: 253 | P29: 7150 | Q29: 0.66354524 | R29: 0.60919084 | S29: - | T29: 0.92978074 | U29: 4078 | V29: 0 | W29: 30 | X29: 4108 | Y29: 1434 | Z29: 5542 | AA29: 1238 | AB29: 705 | AC29: NHS Central East Integrated Care Board
B30: Y02428 | C30: NHS England East Of England | D30: Putnoe Walk In Centre | E30: 0 | F30: 0 | G30: 2335 | H30: 2335 | I30: 0 | J30: 0 | K30: 2335 | L30: 2335 | M30: 0 | N30: 0 | O30: 0 | P30: 0 | Q30: 1 | R30: - | S30: - | T30: 1 | U30: 0 | V30: 0 | W30: 0 | X30: 0 | Y30: 0 | Z30: 0 | AA30: 0 | AB30: 0 | AC30: NHS Central East Integrated Care Board
B31: RQW | C31: NHS England East Of England | D31: The Princess Alexandra Hospital NHS Trust | E31: 9234 | F31: 0 | G31: 2080 | H31: 11314 | I31: 6590 | J31: 0 | K31: 2080 | L31: 8670 | M31: 2644 | N31: 0 | O31: 0 | P31: 2644 | Q31: 0.76630723 | R31: 0.71366688 | S31: - | T31: 1 | U31: 1698 | V31: 0 | W31: 0 | X31: 1698 | Y31: 460 | Z31: 2158 | AA31: 847 | AB31: 328 | AC31: NHS Essex Integrated Care Board
B32: RCX | C32: NHS England East Of England | D32: The Queen Elizabeth Hospital, King's Lynn, NHS Foundation Trust | E32: 6636 | F32: 0 | G32: 1297 | H32: 7933 | I32: 3844 | J32: 0 | K32: 1297 | L32: 5141 | M32: 2792 | N32: 0 | O32: 0 | P32: 2792 | Q32: 0.64805244 | R32: 0.57926462 | S32: - | T32: 1 | U32: 1753 | V32: 0 | W32: 0 | X32: 1753 | Y32: 393 | Z32: 2146 | AA32: 942 | AB32: 154 | AC32: NHS Norfolk and Suffolk Integrated Care Board
B33: RWG | C33: NHS England East Of England | D33: West Hertfordshire Teaching Hospitals NHS Trust | E33: 8453 | F33: 0 | G33: 9276 | H33: 17729 | I33: 6176 | J33: 0 | K33: 9222 | L33: 15398 | M33: 2277 | N33: 0 | O33: 54 | P33: 2331 | Q33: 0.8685205 | R33: 0.73062818 | S33: - | T33: 0.99417853 | U33: 5325 | V33: 0 | W33: 0 | X33: 5325 | Y33: 524 | Z33: 5849 | AA33: 753 | AB33: 15 | AC33: NHS Central East Integrated Care Board
B34: RGR | C34: NHS England East Of England | D34: West Suffolk NHS Foundation Trust | E34: 8264 | F34: 0 | G34: 940 | H34: 9204 | I34: 6573 | J34: 0 | K34: 940 | L34: 7513 | M34: 1691 | N34: 0 | O34: 0 | P34: 1691 | Q34: 0.81627553 | R34: 0.79537754 | S34: - | T34: 1 | U34: 1940 | V34: 0 | W34: 0 | X34: 1940 | Y34: 278 | Z34: 2218 | AA34: 486 | AB34: 149 | AC34: NHS Norfolk and Suffolk Integrated Care Board
B35: G0Q0L | C35: NHS England London | D35: Barking Hospital Utc | E35: 0 | F35: 0 | G35: 2883 | H35: 2883 | I35: 0 | J35: 0 | K35: 2851 | L35: 2851 | M35: 0 | N35: 0 | O35: 32 | P35: 32 | Q35: 0.98890045 | R35: - | S35: - | T35: 0.98890045 | U35: 0 | V35: 0 | W35: 0 | X35: 0 | Y35: 0 | Z35: 0 | AA35: 0 | AB35: 0 | AC35: NHS North East London Integrated Care Board
B36: RF4 | C36: NHS England London | D36: Barking, Havering And Redbridge University Hospitals NHS Trust | E36: 14321 | F36: 2471 | G36: 16018 | H36: 32810 | I36: 9013 | J36: 2212 | K36: 15578 | L36: 26803 | M36: 5308 | N36: 259 | O36: 440 | P36: 6007 | Q36: 0.81691557 | R36: 0.62935549 | S36: 0.89518414 | T36: 0.9725309 | U36: 3593 | V36: 0 | W36: 0 | X36: 3593 | Y36: 2526 | Z36: 6119 | AA36: 1064 | AB36: 568 | AC36: NHS North East London Integrated Care Board
B37: R1H | C37: NHS England London | D37: Barts Health NHS Trust | E37: 27253 | F37: 895 | G37: 18702 | H37: 46850 | I37: 16611 | J37: 894 | K37: 17167 | L37: 34672 | M37: 10642 | N37: 1 | O37: 1535 | P37: 12178 | Q37: 0.74006403 | R37: 0.60951088 | S37: 0.99888268 | T37: 0.91792322 | U37: 3992 | V37: 0 | W37: 24 | X37: 4016 | Y37: 1207 | Z37: 5223 | AA37: 2141 | AB37: 1208 | AC37: NHS North East London Integrated Care Board
B38: AD913 | C38: NHS England London | D38: Beckenham Beacon Ucc | E38: 0 | F38: 0 | G38: 3523 | H38: 3523 | I38: 0 | J38: 0 | K38: 3509 | L38: 3509 | M38: 0 | N38: 0 | O38: 14 | P38: 14 | Q38: 0.99602611 | R38: - | S38: - | T38: 0.99602611 | U38: 0 | V38: 0 | W38: 0 | X38: 0 | Y38: 0 | Z38: 0 | AA38: 0 | AB38: 0 | AC38: NHS South East London Integrated Care Board
B39: RYX | C39: NHS England London | D39: Central London Community Healthcare NHS Trust | E39: 0 | F39: 0 | G39: 13541 | H39: 13541 | I39: 0 | J39: 0 | K39: 13174 | L39: 13174 | M39: 0 | N39: 0 | O39: 367 | P39: 367 | Q39: 0.97289713 | R39: - | S39: - | T39: 0.97289713 | U39: 0 | V39: 0 | W39: 0 | X39: 0 | Y39: 0 | Z39: 0 | AA39: 0 | AB39: 0 | AC39: NHS West and North London Integrated Care Board
B40: RQM | C40: NHS England London | D40: Chelsea And Westminster Hospital NHS Foundation Trust | E40: 21345 | F40: 0 | G40: 6840 | H40: 28185 | I40: 15326 | J40: 0 | K40: 6520 | L40: 21846 | M40: 6019 | N40: 0 | O40: 320 | P40: 6339 | Q40: 0.77509313 | R40: 0.71801359 | S40: - | T40: 0.95321637 | U40: 2966 | V40: 0 | W40: 0 | X40: 2966 | Y40: 316 | Z40: 3282 | AA40: 973 | AB40: 44 | AC40: NHS West and North London Integrated Care Board
B41: RJ6 | C41: NHS England London | D41: Croydon Health Services NHS Trust | E41: 13804 | F41: 0 | G41: 4657 | H41: 18461 | I41: 8710 | J41: 0 | K41: 4657 | L41: 13367 | M41: 5094 | N41: 0 | O41: 0 | P41: 5094 | Q41: 0.72406695 | R41: 0.63097653 | S41: - | T41: 1 | U41: 1090 | V41: 0 | W41: 0 | X41: 1090 | Y41: 150 | Z41: 1240 | AA41: 927 | AB41: 626 | AC41: NHS South West London Integrated Care Board
B42: RVR | C42: NHS England London | D42: Epsom And St Helier University Hospitals NHS Trust | E42: 11635 | F42: 0 | G42: 2921 | H42: 14556 | I42: 7826 | J42: 0 | K42: 2485 | L42: 10311 | M42: 3809 | N42: 0 | O42: 436 | P42: 4245 | Q42: 0.70836768 | R42: 0.6726257 | S42: - | T42: 0.85073605 | U42: 2097 | V42: 0 | W42: 0 | X42: 2097 | Y42: 163 | Z42: 2260 | AA42: 1391 | AB42: 743 | AC42: NHS South West London Integrated Care Board
B43: RJ1 | C43: NHS England London | D43: Guy's And St Thomas' NHS Foundation Trust | E43: 11004 | F43: 0 | G43: 7279 | H43: 18283 | I43: 6731 | J43: 0 | K43: 7062 | L43: 13793 | M43: 4273 | N43: 0 | O43: 217 | P43: 4490 | Q43: 0.75441667 | R43: 0.61168666 | S43: - | T43: 0.97018821 | U43: 2076 | V43: 0 | W43: 0 | X43: 2076 | Y43: 342 | Z43: 2418 | AA43: 232 | AB43: 73 | AC43: NHS South East London Integrated Care Board
B44: K6K0R | C44: NHS England London | D44: Harold Wood Polyclinic Utc | E44: 0 | F44: 0 | G44: 2752 | H44: 2752 | I44: 0 | J44: 0 | K44: 2727 | L44: 2727 | M44: 0 | N44: 0 | O44: 25 | P44: 25 | Q44: 0.9909157 | R44: - | S44: - | T44: 0.9909157 | U44: 0 | V44: 0 | W44: 0 | X44: 0 | Y44: 0 | Z44: 0 | AA44: 0 | AB44: 0 | AC44: NHS North East London Integrated Care Board
...

Sheet Booked Appointments Data
E1: 7 | F1: 8 | G1: 9 | I1: 13 | J1: 14 | K1: 15
B2: Title: | C2: A&E Booked Appointment Attendances
B4: Summary: | C4: A&E booked appointment attendances and performance at an Urgent Treatment Centre made in advance via NHS 111. Please see the Supplementary ECDS Analysis file for further breakdowns of A&E attendance data, this can be found published below this file on the NHS England Website, this provides attendance data split by age groups, gender, ethnicity, chief complaint and provides a data completeness and quality fact sheet.
B6: Period: | C6: September 26
B7: Source: | C7: SDCS data collection - MSitAE
B8: Basis: | C8: Provider
B9: Published: | C9: 8th October 2026
B10: Revised:
B11: Status: | C11: Published
B12: Contact: | C12: Kerry Evert - england.aedata@nhs.net
B14: Provider Level Data
E15: A&E Booked Appointment attendances | I15: A&E Booked Appointments attendances greater than 4 hours from arrival to admission, transfer or discharge | M15: A&E Booked Appointments Performance | Y15: A&E Booked Appointment attendances less than 4 hours from arrival to admission, transfer or discharge
B16: Code | C16: Region | D16: Name | E16: Type 1 Departments - Major A&E | F16: Type 2 Departments - Single Specialty | G16: Type 3 Departments - Other A&E/Minor Injury Unit | H16: Total attendances | I16: Type 1 Departments - Major A&E | J16: Type 2 Departments - Single Specialty | K16: Type 3 Departments - Other A&E/Minor Injury Unit | L16: Booked Appointment Attendances > 4 hours | M16: Percentage in 4 hours or less (all) (Booked Appointments Only) | N16: Percentage in 4 hours or less (type 1) (Booked Appointments Only) | O16: Percentage in 4 hours or less (type 2) (Booked Appointments Only) | P16: Percentage in 4 hours or less (type 3) (Booked Appointments Only) | Q16: Percentage in 4 hours or less (All types excluding Booked Appointments) | R16: Percentage in 4 hours or less (All types including Booked Appointments) | Y16: Type 1 Departments - Major A&E | Z16: Type 2 Departments - Single Specialty | AA16: Type 3 Departments - Other A&E/Minor Injury Unit | AB16: Total Attendances < 4 hours | AG16: Total under 4 hour all types | AH16: Total under 4 hours + booked appointments | AI16: Over 4 hours all types | AJ16: Over 4 hours + booked
B17: - | C17: - | D17: England | E17: 27709 | F17: 499 | G17: 46744 | H17: 74952 | I17: 7952 | J17: 59 | K17: 581 | L17: 8592 | M17: 0.88536663 | N17: 0.71301743 | O17: 0.88176353 | P17: 0.9875706 | Q17: 0.73915041 | R17: 0.74363318 | Y17: 19757 | Z17: 440 | AA17: 46163 | AB17: 66360 | AG17: 1751632 | AH17: 1817992 | AI17: 618159 | AJ17: 626751
B19: RC9 | C19: NHS England East Of England | D19: Bedfordshire Hospitals NHS Foundation Trust | E19: 0 | F19: 0 | G19: 0 | H19: 0 | I19: 0 | J19: 0 | K19: 0 | L19: 0 | M19: - | N19: - | O19: - | P19: - | Q19: 0.74451722 | R19: 0.74451722 | S19: NHS Central East Integrated Care Board | Y19: 0 | Z19: 0 | AA19: 0 | AB19: 0 | AG19: 20233 | AH19: 20233 | AI19: 6943 | AJ19: 6943
B20: RGT | C20: NHS England East Of England | D20: Cambridge University Hospitals NHS Foundation Trust | E20: 276 | F20: 0 | G20: 233 | H20: 509 | I20: 73 | J20: 0 | K20: 9 | L20: 82 | M20: 0.8388998 | N20: 0.73550725 | O20: - | P20: 0.96137339 | Q20: 0.68029591 | R20: 0.68479412 | S20: NHS Central East Integrated Care Board | Y20: 203 | Z20: 0 | AA20: 224 | AB20: 427 | AG20: 11863 | AH20: 12290 | AI20: 5575 | AJ20: 5657
B21: RWH | C21: NHS England East Of England | D21: East And North Hertfordshire Teaching NHS Trust | E21: 0 | F21: 0 | G21: 0 | H21: 0 | I21: 0 | J21: 0 | K21: 0 | L21: 0 | M21: - | N21: - | O21: - | P21: - | Q21: 0.72376043 | R21: 0.72376043 | S21: NHS Central East Integrated Care Board | Y21: 0 | Z21: 0 | AA21: 0 | AB21: 0 | AG21: 13619 | AH21: 13619 | AI21: 5198 | AJ21: 5198
B22: RDE | C22: NHS England East Of England | D22: East Suffolk And North Essex NHS Foundation Trust | E22: 0 | F22: 0 | G22: 0 | H22: 0 | I22: 0 | J22: 0 | K22: 0 | L22: 0 | M22: - | N22: - | O22: - | P22: - | Q22: 0.75728608 | R22: 0.75728608 | S22: NHS Norfolk and Suffolk Integrated Care Board | Y22: 0 | Z22: 0 | AA22: 0 | AB22: 0 | AG22: 19488 | AH22: 19488 | AI22: 6246 | AJ22: 6246
B23: RY4 | C23: NHS England East Of England | D23: Hertfordshire Community NHS Trust | E23: 0 | F23: 0 | G23: 0 | H23: 0 | I23: 0 | J23: 0 | K23: 0 | L23: 0 | M23: - | N23: - | O23: - | P23: - | Q23: 0.94476987 | R23: 0.94476987 | S23: NHS Central East Integrated Care Board | Y23: 0 | Z23: 0 | AA23: 0 | AB23: 0 | AG23: 1129 | AH23: 1129 | AI23: 66 | AJ23: 66
B24: DT301 | C24: NHS England East Of England | D24: Herts Urgent Care (Ascots Lane) | E24: 0 | F24: 0 | G24: 0 | H24: 0 | I24: 0 | J24: 0 | K24: 0 | L24: 0 | M24: - | N24: - | O24: - | P24: - | Q24: 0.94845361 | R24: 0.94845361 | S24: NHS Central East Integrated Care Board | Y24: 0 | Z24: 0 | AA24: 0 | AB24: 0 | AG24: 2208 | AH24: 2208 | AI24: 120 | AJ24: 120
B25: RGP | C25: NHS England East Of England | D25: James Paget University Hospitals NHS Foundation Trust | E25: 0 | F25: 0 | G25: 0 | H25: 0 | I25: 0 | J25: 0 | K25: 0 | L25: 0 | M25: - | N25: - | O25: - | P25: - | Q25: 0.65958122 | R25: 0.65958122 | S25: NHS Norfolk and Suffolk Integrated Care Board | Y25: 0 | Z25: 0 | AA25: 0 | AB25: 0 | AG25: 6237 | AH25: 6237 | AI25: 3219 | AJ25: 3219
